{"uuid": "cb4c1510-bf20-4b8e-9943-df1a0ad7f919", "children": ["9fced712-97aa-4ed0-8ae4-36e0a5fbb1e4"], "befores": [{"name": "api_client", "status": "broken", "statusDetails": {"message": "requests.exceptions.ConnectionError: HTTPConnectionPool(host='myapp', port=8087): Max retries exceeded with url: /login (Caused by NewConnectionError('<urllib3.connection.HTTPConnection object at 0x7f22b30a8880>: Failed to establish a new connection: [Errno -3] Temporary failure in name resolution'))\n", "trace": "  File \"/usr/local/lib/python3.8/site-packages/pluggy/callers.py\", line 187, in _multicall\n    res = hook_impl.function(*args)\n  File \"/usr/local/lib/python3.8/site-packages/_pytest/fixtures.py\", line 1126, in pytest_fixture_setup\n    result = call_fixture_func(fixturefunc, request, kwargs)\n  File \"/usr/local/lib/python3.8/site-packages/_pytest/fixtures.py\", line 925, in call_fixture_func\n    fixture_result = next(generator)\n  File \"/tmp/code/api/conftest.py\", line 14, in api_client\n    api_client.login()\n  File \"/usr/local/lib/python3.8/site-packages/allure_commons/_allure.py\", line 172, in impl\n    return func(*a, **kw)\n  File \"/tmp/code/api/api_client/api_client.py\", line 64, in login\n    return self.invalidlogin(self.username, self.password)\n  File \"/usr/local/lib/python3.8/site-packages/allure_commons/_allure.py\", line 172, in impl\n    return func(*a, **kw)\n  File \"/tmp/code/api/api_client/api_client.py\", line 58, in invalidlogin\n    response = self._request(method=self.POST, location=location, headers=headers, data=body)\n  File \"/usr/local/lib/python3.8/site-packages/allure_commons/_allure.py\", line 172, in impl\n    return func(*a, **kw)\n  File \"/tmp/code/api/api_client/api_client.py\", line 35, in _request\n    res = self.session.request(\n  File \"/usr/local/lib/python3.8/site-packages/requests/sessions.py\", line 542, in request\n    resp = self.send(prep, **send_kwargs)\n  File \"/usr/local/lib/python3.8/site-packages/requests/sessions.py\", line 655, in send\n    r = adapter.send(request, **kwargs)\n  File \"/usr/local/lib/python3.8/site-packages/requests/adapters.py\", line 516, in send\n    raise ConnectionError(e, request=request)\n"}, "steps": [{"name": "Default login", "status": "broken", "statusDetails": {"message": "requests.exceptions.ConnectionError: HTTPConnectionPool(host='myapp', port=8087): Max retries exceeded with url: /login (Caused by NewConnectionError('<urllib3.connection.HTTPConnection object at 0x7f22b30a8880>: Failed to establish a new connection: [Errno -3] Temporary failure in name resolution'))\n", "trace": "  File \"/usr/local/lib/python3.8/site-packages/allure_commons/_allure.py\", line 172, in impl\n    return func(*a, **kw)\n  File \"/tmp/code/api/api_client/api_client.py\", line 64, in login\n    return self.invalidlogin(self.username, self.password)\n  File \"/usr/local/lib/python3.8/site-packages/allure_commons/_allure.py\", line 172, in impl\n    return func(*a, **kw)\n  File \"/tmp/code/api/api_client/api_client.py\", line 58, in invalidlogin\n    response = self._request(method=self.POST, location=location, headers=headers, data=body)\n  File \"/usr/local/lib/python3.8/site-packages/allure_commons/_allure.py\", line 172, in impl\n    return func(*a, **kw)\n  File \"/tmp/code/api/api_client/api_client.py\", line 35, in _request\n    res = self.session.request(\n  File \"/usr/local/lib/python3.8/site-packages/requests/sessions.py\", line 542, in request\n    resp = self.send(prep, **send_kwargs)\n  File \"/usr/local/lib/python3.8/site-packages/requests/sessions.py\", line 655, in send\n    r = adapter.send(request, **kwargs)\n  File \"/usr/local/lib/python3.8/site-packages/requests/adapters.py\", line 516, in send\n    raise ConnectionError(e, request=request)\n"}, "steps": [{"name": "Invalid login with 'Adminadmin' and 'Adminadmin'", "status": "broken", "statusDetails": {"message": "requests.exceptions.ConnectionError: HTTPConnectionPool(host='myapp', port=8087): Max retries exceeded with url: /login (Caused by NewConnectionError('<urllib3.connection.HTTPConnection object at 0x7f22b30a8880>: Failed to establish a new connection: [Errno -3] Temporary failure in name resolution'))\n", "trace": "  File \"/usr/local/lib/python3.8/site-packages/allure_commons/_allure.py\", line 172, in impl\n    return func(*a, **kw)\n  File \"/tmp/code/api/api_client/api_client.py\", line 58, in invalidlogin\n    response = self._request(method=self.POST, location=location, headers=headers, data=body)\n  File \"/usr/local/lib/python3.8/site-packages/allure_commons/_allure.py\", line 172, in impl\n    return func(*a, **kw)\n  File \"/tmp/code/api/api_client/api_client.py\", line 35, in _request\n    res = self.session.request(\n  File \"/usr/local/lib/python3.8/site-packages/requests/sessions.py\", line 542, in request\n    resp = self.send(prep, **send_kwargs)\n  File \"/usr/local/lib/python3.8/site-packages/requests/sessions.py\", line 655, in send\n    r = adapter.send(request, **kwargs)\n  File \"/usr/local/lib/python3.8/site-packages/requests/adapters.py\", line 516, in send\n    raise ConnectionError(e, request=request)\n"}, "steps": [{"name": "Send 'POST' request to '/login'", "status": "broken", "statusDetails": {"message": "requests.exceptions.ConnectionError: HTTPConnectionPool(host='myapp', port=8087): Max retries exceeded with url: /login (Caused by NewConnectionError('<urllib3.connection.HTTPConnection object at 0x7f22b30a8880>: Failed to establish a new connection: [Errno -3] Temporary failure in name resolution'))\n", "trace": "  File \"/usr/local/lib/python3.8/site-packages/allure_commons/_allure.py\", line 172, in impl\n    return func(*a, **kw)\n  File \"/tmp/code/api/api_client/api_client.py\", line 35, in _request\n    res = self.session.request(\n  File \"/usr/local/lib/python3.8/site-packages/requests/sessions.py\", line 542, in request\n    resp = self.send(prep, **send_kwargs)\n  File \"/usr/local/lib/python3.8/site-packages/requests/sessions.py\", line 655, in send\n    r = adapter.send(request, **kwargs)\n  File \"/usr/local/lib/python3.8/site-packages/requests/adapters.py\", line 516, in send\n    raise ConnectionError(e, request=request)\n"}, "parameters": [{"name": "method", "value": "'POST'"}, {"name": "url", "value": "None"}, {"name": "location", "value": "'/login'"}, {"name": "headers", "value": "{'Referer': 'http://http://myapp:8087/login'}"}, {"name": "params", "value": "None"}, {"name": "data", "value": "{'username': 'Adminadmin', 'password': 'Adminadmin'}"}, {"name": "json", "value": "False"}], "start": 1659966990628, "stop": 1659966990633}], "parameters": [{"name": "username", "value": "'Adminadmin'"}, {"name": "password", "value": "'Adminadmin'"}], "start": 1659966990628, "stop": 1659966990633}], "start": 1659966990628, "stop": 1659966990633}], "start": 1659966990628, "stop": 1659966990633}], "start": 1659966990628, "stop": 1659966990814}