{"uuid": "9355e50a-f4ed-4f9e-a592-f6460b74be56", "children": ["a4f176e7-3b1c-41fa-8a3e-20fe19d15c3b"], "befores": [{"name": "browser", "status": "broken", "statusDetails": {"message": "selenium.common.exceptions.InvalidArgumentException: Message: Requested environment is not available\n\n", "trace": "  File \"/usr/local/lib/python3.8/site-packages/pluggy/callers.py\", line 187, in _multicall\n    res = hook_impl.function(*args)\n  File \"/usr/local/lib/python3.8/site-packages/_pytest/fixtures.py\", line 1126, in pytest_fixture_setup\n    result = call_fixture_func(fixturefunc, request, kwargs)\n  File \"/usr/local/lib/python3.8/site-packages/_pytest/fixtures.py\", line 925, in call_fixture_func\n    fixture_result = next(generator)\n  File \"/tmp/code/ui/conftest.py\", line 72, in browser\n    browser = get_driver(config)\n  File \"/tmp/code/ui/conftest.py\", line 61, in get_driver\n    browser = webdriver.Remote(command_executor=f\"http://selenoid:4444/wd/hub\",\n  File \"/usr/local/lib/python3.8/site-packages/selenium/webdriver/remote/webdriver.py\", line 157, in __init__\n    self.start_session(capabilities, browser_profile)\n  File \"/usr/local/lib/python3.8/site-packages/selenium/webdriver/remote/webdriver.py\", line 252, in start_session\n    response = self.execute(Command.NEW_SESSION, parameters)\n  File \"/usr/local/lib/python3.8/site-packages/selenium/webdriver/remote/webdriver.py\", line 321, in execute\n    self.error_handler.check_response(response)\n  File \"/usr/local/lib/python3.8/site-packages/selenium/webdriver/remote/errorhandler.py\", line 242, in check_response\n    raise exception_class(message, screen, stacktrace)\n"}, "start": 1659984512577, "stop": 1659984512579}], "start": 1659984512577, "stop": 1659984512621}